Traceback (most recent call last):
  File "/home/dev/.local/lib/python3.10/site-packages/jupyter_cache/executors/utils.py", line 58, in single_nb_execution
    executenb(
  File "/home/dev/.local/lib/python3.10/site-packages/nbclient/client.py", line 1305, in execute
    return NotebookClient(nb=nb, resources=resources, km=km, **kwargs).execute()
  File "/home/dev/.local/lib/python3.10/site-packages/jupyter_core/utils/__init__.py", line 166, in wrapped
    return loop.run_until_complete(inner)
  File "/usr/lib/python3.10/asyncio/base_events.py", line 646, in run_until_complete
    return future.result()
  File "/home/dev/.local/lib/python3.10/site-packages/nbclient/client.py", line 705, in async_execute
    await self.async_execute_cell(
  File "/home/dev/.local/lib/python3.10/site-packages/nbclient/client.py", line 1058, in async_execute_cell
    await self._check_raise_for_error(cell, cell_index, exec_reply)
  File "/home/dev/.local/lib/python3.10/site-packages/nbclient/client.py", line 914, in _check_raise_for_error
    raise CellExecutionError.from_cell_and_msg(cell, exec_reply_content)
nbclient.exceptions.CellExecutionError: An error occurred while executing the following cell:
------------------
jk = BankAccount("Jan Kowalski", 1000)
print(jk.__balance) # bÅ‚Ä…d!
------------------


[0;31m---------------------------------------------------------------------------[0m
[0;31mAttributeError[0m                            Traceback (most recent call last)
Cell [0;32mIn[29], line 2[0m
[1;32m      1[0m jk [38;5;241m=[39m BankAccount([38;5;124m"[39m[38;5;124mJan Kowalski[39m[38;5;124m"[39m, [38;5;241m1000[39m)
[0;32m----> 2[0m [38;5;28mprint[39m([43mjk[49m[38;5;241;43m.[39;49m[43m__balance[49m) [38;5;66;03m# bÅ‚Ä…d![39;00m

[0;31mAttributeError[0m: 'BankAccount' object has no attribute '__balance'

