Traceback (most recent call last):
  File "/home/dev/anaconda3/envs/jb/lib/python3.8/site-packages/jupyter_cache/executors/utils.py", line 51, in single_nb_execution
    executenb(
  File "/home/dev/anaconda3/envs/jb/lib/python3.8/site-packages/nbclient/client.py", line 1112, in execute
    return NotebookClient(nb=nb, resources=resources, km=km, **kwargs).execute()
  File "/home/dev/anaconda3/envs/jb/lib/python3.8/site-packages/nbclient/util.py", line 74, in wrapped
    return just_run(coro(*args, **kwargs))
  File "/home/dev/anaconda3/envs/jb/lib/python3.8/site-packages/nbclient/util.py", line 53, in just_run
    return loop.run_until_complete(coro)
  File "/home/dev/anaconda3/envs/jb/lib/python3.8/asyncio/base_events.py", line 616, in run_until_complete
    return future.result()
  File "/home/dev/anaconda3/envs/jb/lib/python3.8/site-packages/nbclient/client.py", line 553, in async_execute
    await self.async_execute_cell(
  File "/home/dev/anaconda3/envs/jb/lib/python3.8/site-packages/nbclient/client.py", line 857, in async_execute_cell
    self._check_raise_for_error(cell, exec_reply)
  File "/home/dev/anaconda3/envs/jb/lib/python3.8/site-packages/nbclient/client.py", line 760, in _check_raise_for_error
    raise CellExecutionError.from_cell_and_msg(cell, exec_reply_content)
nbclient.exceptions.CellExecutionError: An error occurred while executing the following cell:
------------------
jk = BankAccount("Jan Kowalski", 1000)
print(jk.__balance) # bÅ‚Ä…d!
------------------

[0;31m---------------------------------------------------------------------------[0m
[0;31mAttributeError[0m                            Traceback (most recent call last)
[0;32m<ipython-input-29-e6f05cd5e055>[0m in [0;36m<module>[0;34m[0m
[1;32m      1[0m [0mjk[0m [0;34m=[0m [0mBankAccount[0m[0;34m([0m[0;34m"Jan Kowalski"[0m[0;34m,[0m [0;36m1000[0m[0;34m)[0m[0;34m[0m[0;34m[0m[0m
[0;32m----> 2[0;31m [0mprint[0m[0;34m([0m[0mjk[0m[0;34m.[0m[0m__balance[0m[0;34m)[0m [0;31m# bÅ‚Ä…d![0m[0;34m[0m[0;34m[0m[0m
[0m
[0;31mAttributeError[0m: 'BankAccount' object has no attribute '__balance'
AttributeError: 'BankAccount' object has no attribute '__balance'

